Workbook

Sheet Kosten_Beispiel
A1: Ich bin fix und Fertig, Haus!
B3: Grunderwerbssteuer Prozentsatz [%] | C3: 6.5
A7: Grundstück | B7: Position | C7: Kosten [€] | D7: erledigt [%] | E7: bereits bezahlt [€] | F7: Summe
B8: Grundstückspreis | C8: 200000 | D8: 100 | E8: =C8*D8/100 -> 200000
B9: Grunderwerbssteuer | C9: =C8*C3/100 -> 13000 | D9: 100 | E9: =C9*D9/100 -> 13000
B10: Stadt Bearbeitungsgebühr | C10: 1300 | D10: 100 | E10: =C10*D10/100 -> 1300
B11: Notar, Kauf d. Grundstücks (ca 1%) | C11: 2000 | D11: 100 | E11: =C11*D11/100 -> 2000
B12: Notar, Grundbuchänderung | C12: 1000 | D12: 100 | E12: =C12*D12/100 -> 1000
B13: Statd, Grundbuchänderung | C13: 700 | D13: 100 | E13: =C13*D13/100 -> 700
F15: =SUM(E8:E14) -> 218000
A19: Garage & Solar | B19: Position | C19: Kosten [€] | D19: erledigt [%] | E19: bereits bezahlt [€] | F19: Summe
B20: Solaranlage | C20: 20000 | D20: 100 | E20: =C20*D20/100 -> 20000
B21: Bodenplatte | C21: 7000 | D21: 100 | E21: =C21*D21/100 -> 7000
B22: Garage | C22: 30000 | D22: 100 | E22: =C22*D22/100 -> 30000
B23: Vermesser | C23: 500 | D23: 100 | E23: =C23*D23/100 -> 500
E24: =C24*D24/100 -> 0
F25: =SUM(E20:E24) -> 57500
A29: Baunebenkosten | B29: Position | C29: Kosten [€] | D29: erledigt [%] | E29: bereits bezahlt [€] | F29: Summe
A30: Garten | B30: Terrasse | C30: 7500 | D30: 100 | E30: =C30*D30/100 -> 7500
B31: Pflasterarbeiten | C31: 11000 | D31: 100 | E31: =C31*D31/100 -> 11000
B32: Zaun | C32: 4000 | D32: 100 | E32: =C32*D32/100 -> 4000
B33: Rasen | C33: 1000 | D33: 100 | E33: =C33*D33/100 -> 1000
B34: Maulwurfsperre | C34: 500 | D34: 100 | E34: =C34*D34/100 -> 500
B35: Rasen verlegen | C35: 2000 | D35: 100 | E35: =C35*D35/100 -> 2000
B36: Vorgarten | C36: 4000 | D36: 100 | E36: =C36*D36/100 -> 4000
A37: Erdarbeiten | B37: Baustelleneinrichtung | C37: 300 | D37: 100 | E37: =C37*D37/100 -> 300
B38: Abtragen Grasnarbe | C38: 2000 | D38: 100 | E38: =C38*D38/100 -> 2000
B39: 30 cm Mutterboden auf Grundstück | C39: 400 | D39: 100 | E39: =C39*D39/100 -> 400
B40: Auskoffern Bodenplatte | C40: 2500 | D40: 100 | E40: =C40*D40/100 -> 2500
B41: Auskoffern Einfahrt, Garage | C41: 1500 | D41: 100 | E41: =C41*D41/100 -> 1500
B42: Nachverdichten | C42: 200 | D42: 100 | E42: =C42*D42/100 -> 200
B43: Geotextil | C43: 800 | D43: 100 | E43: =C43*D43/100 -> 800
B44: Ringerder & Klemmen | C44: 600 | D44: 100 | E44: =C44*D44/100 -> 600
B45: Füllkies Haus | C45: 4500 | D45: 100 | E45: =C45*D45/100 -> 4500
B46: Füllkies Einfarht, Garage | C46: 3000 | D46: 100 | E46: =C46*D46/100 -> 3000
B47: Lastplattendruckversuch | C47: 300 | D47: 100 | E47: =C47*D47/100 -> 300
A49: Erdleitungen | B49: Regenwasser Leitungen | C49: 1500 | D49: 100 | E49: =C49*D49/100 -> 1500
B50: Schmutzwasserleitungen | C50: 1500 | D50: 100 | E50: =C50*D50/100 -> 1500
B51: Revisionsschacht | C51: 1600 | D51: 100 | E51: =C51*D51/100 -> 1600
B52: Kanalanschluss | C52: 600 | D52: 100 | E52: =C52*D52/100 -> 600
...

Sheet Kosten_Meine_Daten
A1: Ich bin fix und Fertig, Haus!
B3: Grunderwerbssteuer Prozentsatz [%] | C3: 6.5
A7: Grundstück | B7: Position | C7: Kosten [€] | D7: erledigt [%] | E7: bereits bezahlt [€] | F7: Summe
B8: Grundstückspreis | C8: 0 | D8: 0 | E8: =C8*D8/100 -> 0
B9: Grunderwerbssteuer | C9: =C8*C3/100 -> 0 | D9: 0 | E9: =C9*D9/100 -> 0
B10: Stadt Bearbeitungsgebühr | C10: 0 | D10: 0 | E10: =C10*D10/100 -> 0
B11: Notar, Kauf d. Grundstücks (ca 1%) | C11: 0 | D11: 0 | E11: =C11*D11/100 -> 0
B12: Notar, Grundbuchänderung | C12: 0 | D12: 0 | E12: =C12*D12/100 -> 0
B13: Statd, Grundbuchänderung | C13: 0 | D13: 0 | E13: =C13*D13/100 -> 0
F15: =SUM(E8:E14) -> 0
A19: Garage & Solar | B19: Position | C19: Kosten [€] | D19: erledigt [%] | E19: bereits bezahlt [€] | F19: Summe
B20: Solaranlage | C20: 0 | D20: 0 | E20: =C20*D20/100 -> 0
B21: Bodenplatte | C21: 0 | D21: 0 | E21: =C21*D21/100 -> 0
B22: Garage | C22: 0 | D22: 0 | E22: =C22*D22/100 -> 0
B23: Vermesser | C23: 0 | D23: 0 | E23: =C23*D23/100 -> 0
E24: =C24*D24/100 -> 0
F25: =SUM(E20:E24) -> 0
A29: Baunebenkosten | B29: Position | C29: Kosten [€] | D29: erledigt [%] | E29: bereits bezahlt [€] | F29: Summe
A30: Garten | B30: Terrasse | C30: 0 | D30: 0 | E30: =C30*D30/100 -> 0
B31: Pflasterarbeiten | C31: 0 | D31: 0 | E31: =C31*D31/100 -> 0
B32: Zaun | C32: 0 | D32: 0 | E32: =C32*D32/100 -> 0
B33: Rasen | C33: 0 | D33: 0 | E33: =C33*D33/100 -> 0
B34: Maulwurfsperre | C34: 0 | D34: 0 | E34: =C34*D34/100 -> 0
B35: Rasen verlegen | C35: 0 | D35: 0 | E35: =C35*D35/100 -> 0
B36: Vorgarten | C36: 0 | D36: 0 | E36: =C36*D36/100 -> 0
A37: Erdarbeiten | B37: Baustelleneinrichtung | C37: 0 | D37: 0 | E37: =C37*D37/100 -> 0
B38: Abtragen Grasnarbe | C38: 0 | D38: 0 | E38: =C38*D38/100 -> 0
B39: 30 cm Mutterboden auf Grundstück | C39: 0 | D39: 0 | E39: =C39*D39/100 -> 0
B40: Auskoffern Bodenplatte | C40: 0 | D40: 0 | E40: =C40*D40/100 -> 0
B41: Auskoffern Einfahrt, Garage | C41: 0 | D41: 0 | E41: =C41*D41/100 -> 0
B42: Nachverdichten | C42: 0 | D42: 0 | E42: =C42*D42/100 -> 0
B43: Geotextil | C43: 0 | D43: 0 | E43: =C43*D43/100 -> 0
B44: Ringerder & Klemmen | C44: 0 | D44: 0 | E44: =C44*D44/100 -> 0
B45: Füllkies Haus | C45: 0 | D45: 0 | E45: =C45*D45/100 -> 0
B46: Füllkies Einfarht, Garage | C46: 0 | D46: 0 | E46: =C46*D46/100 -> 0
B47: Lastplattendruckversuch | C47: 0 | D47: 0 | E47: =C47*D47/100 -> 0
A49: Erdleitungen | B49: Regenwasser Leitungen | C49: 0 | D49: 0 | E49: =C49*D49/100 -> 0
B50: Schmutzwasserleitungen | C50: 0 | D50: 0 | E50: =C50*D50/100 -> 0
B51: Revisionsschacht | C51: 0 | D51: 0 | E51: =C51*D51/100 -> 0
B52: Kanalanschluss | C52: 0 | D52: 0 | E52: =C52*D52/100 -> 0
...

Sheet Finanzierung
A1: Darlehen [Euro] | B1: 800000
A2: Tilgung [%] | B2: 1.5
A3: Zinssatz [%] | B3: 3.2
A4: Gemeinsames Einkommen (Netto) [Euro] | B4: 6000
A5: Rate [Euro / Monat] | B5: =B1*(B2*B3)/100/12 -> 3200
A6: Sparrendite [%] | B6: 6
B8: Jahr | C8: 1 | D8: 2 | E8: 3 | F8: 4 | G8: 5 | H8: 6 | I8: 7 | J8: 8 | K8: 9 | L8: 10 | M8: 15 | N8: 20 | O8: 25 | P8: 30
A9: Variante ohne Sparen | B9: Restschuld | C9: =Zinseszinz!$C15 -> 787079.24 | D9: =Zinseszinz!$C27 -> 773670.24 | E9: =Zinseszinz!$C39 -> 759825.81 | F9: =Zinseszinz!$C51 -> 745531.8 | G9: =Zinseszinz!$C63 -> 730773.61 | H9: =Zinseszinz!$C75 -> 715536.17 | I9: =Zinseszinz!$C87 -> 699803.92 | J9: =Zinseszinz!$C99 -> 683560.79 | K9: =Zinseszinz!$C111 -> 666790.19 | L9: =Zinseszinz!$C123 -> 649474.98 | M9: =Zinseszinz!$C183 -> 554090.47 | N9: =Zinseszinz!$C243 -> 442179.55 | O9: =Zinseszinz!$C303 -> 310878.82 | P9: =Zinseszinz!$C363 -> 156828.8
B12: Jahr | C12: 1 | D12: 2 | E12: 3 | F12: 4 | G12: 5 | H12: 6 | I12: 7 | J12: 8 | K12: 9 | L12: 10 | M12: 15 | N12: 20 | O12: 25 | P12: 30
A13: Variante mit Sparen 30% der Rate | B13: Restschuld | C13: =Zinseszinz!$L19 -> 798258.77 | D13: =Zinseszinz!$L31 -> 796903.29 | E13: =Zinseszinz!$L43 -> 795503.78 | F13: =Zinseszinz!$L55 -> 794058.83 | G13: =Zinseszinz!$L67 -> 792566.96 | H13: =Zinseszinz!$L79 -> 791026.64 | I13: =Zinseszinz!$L91 -> 789436.31 | J13: =Zinseszinz!$L103 -> 787794.33 | K13: =Zinseszinz!$L115 -> 786099.02 | L13: =Zinseszinz!$L127 -> 784348.67 | M13: =Zinseszinz!$L187 -> 774706.46 | N13: =Zinseszinz!$L247 -> 763393.64 | O13: =Zinseszinz!$L307 -> 750120.75 | P13: =Zinseszinz!$L367 -> 734548.18
B14: Angespart | C14: =Zinseszinz!O20 -> 16989.409 | D14: =Zinseszinz!$O32 -> 29879.419 | E14: =Zinseszinz!$O44 -> 43564.456 | F14: =Zinseszinz!$O56 -> 58093.556 | G14: =Zinseszinz!$O68 -> 73518.779 | H14: =Zinseszinz!$O80 -> 89895.397 | I14: =Zinseszinz!$O92 -> 107282.09 | J14: =Zinseszinz!$O104 -> 125741.15 | K14: =Zinseszinz!$O116 -> 145338.73 | L14: =Zinseszinz!$O128 -> 166145.05 | M14: =Zinseszinz!$O188 -> 291084 | N14: =Zinseszinz!$O248 -> 459607.93 | O14: =Zinseszinz!$O308 -> 686921.45 | P14: =Zinseszinz!$O368 -> 993533.33
B15: Summe | C15: =C14-C13 -> -781269.36 | D15: =D14-D13 -> -767023.87 | E15: =E14-E13 -> -751939.33 | F15: =F14-F13 -> -735965.28 | G15: =G14-G13 -> -719048.18 | H15: =H14-H13 -> -701131.25 | I15: =I14-I13 -> -682154.22 | J15: =J14-J13 -> -662053.17 | ... P15: =P14-P13 -> 258985.16

Sheet Zinseszinz
A1: Nebenrechung Zinsen | G1: Rate minus 30% | H1: =(Finanzierung!B5)*0.7 -> 2240 | S1: Für die Grafik
A2: Monat | B2: Rate | C2: Restbetrag | D2: Zinsbetrag | E2: Tilgungsbetrag | G2: Tilgung | H2: =H1/L3*12*100-Finanzierung!B3 -> 0.16 | J2: Monat | K2: Rate | L2: Restbetrag | M2: Zinsbetrag | N2: Tilgungsbetrag | O2: Gespart
C3: =Finanzierung!$B$1 -> 800000 | D3: =C3*Finanzierung!$B$3/100/12 -> 2133.3333 | E3: =C3*Finanzierung!$B$2/100/12 -> 1000 | G3: Sparrate | H3: =B4-H1 -> 960 | L3: =Finanzierung!$B$1 -> 800000 | M3: =L3*Finanzierung!$B$3/100/12 -> 2133.3333 | N3: =H1-M3 -> 106.66667 | S3: Jahre | T3: Variante 1 | U3: Variante 2
A4: 1 | B4: =Finanzierung!$B$5 -> 3200 | C4: =C3-E3 -> 799000 | D4: =C4*Finanzierung!$B$3/100/12 -> 2130.6667 | E4: =B4-D4 -> 1069.3333 | J4: 1 | K4: =$H$1 -> 2240 | L4: =L3-N3 -> 799893.33 | M4: =L4*Finanzierung!$B$3/100/12 -> 2133.0489 | N4: =K4-M4 -> 106.95111 | O4: =H3 -> 960 | S4: =J4/12 -> 0.083333333 | T4: =-C4 -> -799000 | U4: =O4-L4 -> -798933.33
A5: 2 | B5: =Finanzierung!$B$5 -> 3200 | C5: =C4-E4 -> 797930.67 | D5: =C5*Finanzierung!$B$3/100/12 -> 2127.8151 | E5: =B5-D5 -> 1072.1849 | J5: 2 | K5: =$H$1 -> 2240 | L5: =L4-N4 -> 799786.38 | M5: =L5*Finanzierung!$B$3/100/12 -> 2132.7637 | N5: =K5-M5 -> 107.23631 | O5: =O4*(1+Finanzierung!$B$6/100/12)+$H$3 -> 1924.8 | S5: =J5/12 -> 0.16666667 | T5: =-C5 -> -797930.67 | U5: =O5-L5 -> -797861.58
A6: 3 | B6: =Finanzierung!$B$5 -> 3200 | C6: =C5-E5 -> 796858.48 | D6: =C6*Finanzierung!$B$3/100/12 -> 2124.956 | E6: =B6-D6 -> 1075.044 | J6: 3 | K6: =$H$1 -> 2240 | L6: =L5-N5 -> 799679.15 | M6: =L6*Finanzierung!$B$3/100/12 -> 2132.4777 | N6: =K6-M6 -> 107.52228 | O6: =O5*(1+Finanzierung!$B$6/100/12)+$H$3 -> 2894.424 | S6: =J6/12 -> 0.25 | T6: =-C6 -> -796858.48 | U6: =O6-L6 -> -796784.72
A7: 4 | B7: =Finanzierung!$B$5 -> 3200 | C7: =C6-E6 -> 795783.44 | D7: =C7*Finanzierung!$B$3/100/12 -> 2122.0892 | E7: =B7-D7 -> 1077.9108 | J7: 4 | K7: =$H$1 -> 2240 | L7: =L6-N6 -> 799571.62 | M7: =L7*Finanzierung!$B$3/100/12 -> 2132.191 | N7: =K7-M7 -> 107.809 | O7: =O6*(1+Finanzierung!$B$6/100/12)+$H$3 -> 3868.8961 | S7: =J7/12 -> 0.33333333 | T7: =-C7 -> -795783.44 | U7: =O7-L7 -> -795702.73
A8: 5 | B8: =Finanzierung!$B$5 -> 3200 | C8: =C7-E7 -> 794705.53 | D8: =C8*Finanzierung!$B$3/100/12 -> 2119.2147 | E8: =B8-D8 -> 1080.7853 | J8: 5 | K8: =$H$1 -> 2240 | L8: =L7-N7 -> 799463.81 | M8: =L8*Finanzierung!$B$3/100/12 -> 2131.9035 | N8: =K8-M8 -> 108.09649 | O8: =O7*(1+Finanzierung!$B$6/100/12)+$H$3 -> 4848.2406 | S8: =J8/12 -> 0.41666667 | T8: =-C8 -> -794705.53 | U8: =O8-L8 -> -794615.57
A9: 6 | B9: =Finanzierung!$B$5 -> 3200 | C9: =C8-E8 -> 793624.74 | D9: =C9*Finanzierung!$B$3/100/12 -> 2116.3326 | E9: =B9-D9 -> 1083.6674 | J9: 6 | K9: =$H$1 -> 2240 | L9: =L8-N8 -> 799355.72 | M9: =L9*Finanzierung!$B$3/100/12 -> 2131.6152 | N9: =K9-M9 -> 108.38475 | O9: =O8*(1+Finanzierung!$B$6/100/12)+$H$3 -> 5832.4818 | S9: =J9/12 -> 0.5 | T9: =-C9 -> -793624.74 | U9: =O9-L9 -> -793523.24
A10: 7 | B10: =Finanzierung!$B$5 -> 3200 | C10: =C9-E9 -> 792541.07 | D10: =C10*Finanzierung!$B$3/100/12 -> 2113.4429 | E10: =B10-D10 -> 1086.5571 | J10: 7 | K10: =$H$1 -> 2240 | L10: =L9-N9 -> 799247.33 | M10: =L10*Finanzierung!$B$3/100/12 -> 2131.3262 | N10: =K10-M10 -> 108.67378 | O10: =O9*(1+Finanzierung!$B$6/100/12)+$H$3 -> 6821.6442 | S10: =J10/12 -> 0.58333333 | T10: =-C10 -> -792541.07 | U10: =O10-L10 -> -792425.69
A11: 8 | B11: =Finanzierung!$B$5 -> 3200 | C11: =C10-E10 -> 791454.52 | D11: =C11*Finanzierung!$B$3/100/12 -> 2110.5454 | E11: =B11-D11 -> 1089.4546 | J11: 8 | K11: =$H$1 -> 2240 | L11: =L10-N10 -> 799138.66 | M11: =L11*Finanzierung!$B$3/100/12 -> 2131.0364 | N11: =K11-M11 -> 108.96357 | O11: =O10*(1+Finanzierung!$B$6/100/12)+$H$3 -> 7815.7524 | S11: =J11/12 -> 0.66666667 | T11: =-C11 -> -791454.52 | U11: =O11-L11 -> -791322.91
A12: 9 | B12: =Finanzierung!$B$5 -> 3200 | C12: =C11-E11 -> 790365.06 | D12: =C12*Finanzierung!$B$3/100/12 -> 2107.6402 | E12: =B12-D12 -> 1092.3598 | J12: 9 | K12: =$H$1 -> 2240 | L12: =L11-N11 -> 799029.7 | M12: =L12*Finanzierung!$B$3/100/12 -> 2130.7459 | N12: =K12-M12 -> 109.25414 | O12: =O11*(1+Finanzierung!$B$6/100/12)+$H$3 -> 8814.8312 | S12: =J12/12 -> 0.75 | T12: =-C12 -> -790365.06 | U12: =O12-L12 -> -790214.86
A13: 10 | B13: =Finanzierung!$B$5 -> 3200 | C13: =C12-E12 -> 789272.7 | D13: =C13*Finanzierung!$B$3/100/12 -> 2104.7272 | E13: =B13-D13 -> 1095.2728 | J13: 10 | K13: =$H$1 -> 2240 | L13: =L12-N12 -> 798920.44 | M13: =L13*Finanzierung!$B$3/100/12 -> 2130.4545 | N13: =K13-M13 -> 109.54549 | O13: =O12*(1+Finanzierung!$B$6/100/12)+$H$3 -> 9818.9054 | S13: =J13/12 -> 0.83333333 | T13: =-C13 -> -789272.7 | U13: =O13-L13 -> -789101.54
A14: 11 | B14: =Finanzierung!$B$5 -> 3200 | C14: =C13-E13 -> 788177.43 | D14: =C14*Finanzierung!$B$3/100/12 -> 2101.8065 | E14: =B14-D14 -> 1098.1935 | J14: 11 | K14: =$H$1 -> 2240 | L14: =L13-N13 -> 798810.9 | M14: =L14*Finanzierung!$B$3/100/12 -> 2130.1624 | N14: =K14-M14 -> 109.83761 | O14: =O13*(1+Finanzierung!$B$6/100/12)+$H$3 -> 10828 | S14: =J14/12 -> 0.91666667 | T14: =-C14 -> -788177.43 | U14: =O14-L14 -> -787982.9
A15: 12 | B15: =Finanzierung!$B$5 -> 3200 | C15: =C14-E14 -> 787079.24 | D15: =C15*Finanzierung!$B$3/100/12 -> 2098.878 | E15: =B15-D15 -> 1101.122 | J15: 12 | K15: =$H$1 -> 2240 | L15: =L14-N14 -> 798701.06 | M15: =L15*Finanzierung!$B$3/100/12 -> 2129.8695 | N15: =K15-M15 -> 110.13051 | O15: =O14*(1+Finanzierung!$B$6/100/12)+$H$3 -> 11842.14 | S15: =J15/12 -> 1 | T15: =-C15 -> -787079.24 | U15: =O15-L15 -> -786858.92
A16: 13 | B16: =Finanzierung!$B$5 -> 3200 | C16: =C15-E15 -> 785978.11 | D16: =C16*Finanzierung!$B$3/100/12 -> 2095.9416 | E16: =B16-D16 -> 1104.0584 | J16: 13 | K16: =$H$1 -> 2240 | L16: =L15-N15 -> 798590.93 | M16: =L16*Finanzierung!$B$3/100/12 -> 2129.5758 | N16: =K16-M16 -> 110.42419 | O16: =O15*(1+Finanzierung!$B$6/100/12)+$H$3 -> 12861.351 | S16: =J16/12 -> 1.0833333 | T16: =-C16 -> -785978.11 | U16: =O16-L16 -> -785729.58
... A483: 480 | B483: =Finanzierung!$B$5 -> 3200 | C483: =C482-E482 -> -235968.3 | D483: =C483*Finanzierung!$B$3/100/12 -> -629.24879 | E483: =B483-D483 -> 3829.2488 | J483: 480 | K483: =$H$1 -> 2240 | L483: =L482-N482 -> 696379.3 | M483: =L483*Finanzierung!$B$3/100/12 -> 1857.0115 | N483: =K483-M483 -> 382.98854 | O483: =O482*(1+Finanzierung!$B$6/100/12)+$H$3 -> 1911831.1 | S483: =J483/12 -> 40 | T483: =-C483 -> 235968.3 | U483: =O483-L483 -> 1215451.8
